<?xml version="1.0" encoding="utf-8"?>
<!-- This URDF was automatically created by SolidWorks to URDF Exporter! Originally created by
Stephen Brawner (brawner@gmail.com) 
     Commit Version: 1.6.0-4-g7f85cfe  Build Version: 1.6.7995.38578
     For more information, please see http://wiki.ros.org/sw_urdf_exporter -->
<robot
  name="lamp">
  <link
    name="base">
    <inertial>
      <origin
        xyz="0 0 0"
        rpy="0 0 0" />
      <mass
        value="0.5" />
      <inertia
        ixx="0.004"
        ixy="0."
        ixz="0."
        iyy="0.008"
        iyz="0."
        izz="0.004" />
    </inertial>
    <visual>
      <origin
        xyz="0 0 0"
        rpy="0 0 0" />
      <geometry>
        <mesh
          filename="./meshes/base.obj" />
      </geometry>
      <material
        name="">
        <color
          rgba="1 1 1 1" />
      </material>
    </visual>
    <visual>
      <origin
        xyz="0 0.01 0"
        rpy="1.570748 0 0" />
      <geometry>
        <cylinder
            length="0.02"
            radius="0.04" />
      </geometry>
      <material
        name="">
        <color
          rgba="1 1 1 1" />
      </material>
    </visual>
    <collision>
      <origin
        xyz="0 0.01 0"
        rpy="1.570748 0 0" />
      <geometry>
        <cylinder
            length="0.02"
            radius="0.04" />
      </geometry>
      <material
        name="">
        <color
          rgba="1 1 1 1" />
      </material>
    </collision>
  </link>
  <link
    name="rod1">
    <visual>
      <origin
        xyz="0 -0.05 0"
        rpy="0 0 0" />
      <geometry>
        <mesh
          filename="./meshes/rod.obj" />
      </geometry>
      <material
        name="">
        <color
          rgba="1 1 1 1" />
      </material>
    </visual>
  </link>
  <joint
    name="base_rod1_joint"
    type="revolute">
    <origin
      xyz="0 0.05 0"
      rpy="-0.05 0 0" />
    <parent
      link="base" />
    <child
      link="rod1" />
    <axis
      xyz="1 0 0" />
    <limit
      lower="-0.8"
      upper="2.0"
      effort="23.7"
      velocity="30.1" />
  </joint>
  <link
    name="rod2">
    <inertial>
      <origin
        xyz="0 0 0"
        rpy="0 0 0" />
      <mass
        value="0.1" />
      <inertia
        ixx="0.0008"
        ixy="0."
        ixz="0."
        iyy="0.0008"
        iyz="0."
        izz="0.0008" />
    </inertial>
    <visual>
      <origin
        xyz="0 -0.05 0"
        rpy="0 0 0" />
      <geometry>
        <mesh
          filename="./meshes/rod.obj" />
      </geometry>
      <material
        name="">
        <color
          rgba="1 1 1 1" />
      </material>
    </visual>
  </link>
  <joint
    name="rod1_rod2_joint"
    type="revolute">
    <origin
      xyz="0 0.147 -0.118"
      rpy="1.5 0 0" />
    <parent
      link="rod1" />
    <child
      link="rod2" />
    <axis
      xyz="1 0 0" />
    <limit
      lower="-1.0472"
      upper="1.0472"
      effort="23.7"
      velocity="30.1" />
  </joint>
  <link
    name="light">
    <inertial>
      <origin
        xyz="0 0 0"
        rpy="0 0 0" />
      <mass
        value="0.5" />
      <inertia
        ixx="0.004"
        ixy="0."
        ixz="0."
        iyy="0.008"
        iyz="0."
        izz="0.004" />
    </inertial>
    <visual>
      <origin
        xyz="0 -0.197 0.118"
        rpy="0 0 0" />
      <geometry>
        <mesh
          filename="./meshes/light.obj" />
      </geometry>
      <material
        name="">
        <color
          rgba="1 1 1 1" />
      </material>
    </visual>
    <collision>
      <origin
        xyz="0 -0.197 0.118"
        rpy="0 0 0" />
      <geometry>
        <mesh
          filename="./meshes/light.obj" />
      </geometry>
    </collision>
  </link>
  <joint
    name="rod2_light_joint"
    type="revolute">
    <origin
      xyz="0 0.147 -0.118"
      rpy="-0.1 0 0" />
    <parent
      link="rod2" />
    <child
      link="light" />
    <axis
      xyz="1 0 0" />
    <limit
      lower="-1.2"
      upper="0.6"
      effort="23.7"
      velocity="30.1" />
  </joint>
</robot>